<?xml version="1.0"?>
<robot xmlns:xacro="http://www.ros.org/wiki/xacro" name="cyton_gamma_300">

    <!-- Initial footprint motor used here -->
    <xacro:macro name="base_footprint" params="prefix">
        <link name="base_footprint">
            <visual>
                <origin xyz="0 0 0" rpy="0 0 0"/>
                <geometry>
                    <sphere radius="0.001" />
                </geometry>
                <material name="white">
                    <color rgba="1 1 1 1"/>
                </material>
            </visual>
        </link>

        <joint name="base_joint" type="fixed">
            <parent link="base_footprint" />
            <child link="${prefix}base_link" />
            <origin xyz="0.0 0.0 0.0" rpy="0 0 0" />
        </joint>
    </xacro:macro>

    <xacro:macro name="cyton_gamma_300" params="prefix virtual_ee">
        <!-- Base of robot here -->
        <link name="${prefix}base_link">
            <visual>
                <origin xyz="0 0 0" rpy="0 0 0"/>
                <geometry>
                    <mesh filename="package://cyton_gamma_300_description/meshes/gamma_base.dae"/>
                </geometry>
            </visual>
            <collision>
                <origin xyz="0 0.0115 0.047"/>
                <geometry>
                    <box size="0.154 0.177 0.094"/>
                </geometry>
            </collision>
        </link>

        <!-- First motor located here -->
        <joint name="${prefix}shoulder_roll_joint" type="revolute">
            <parent link="${prefix}base_link" />
            <child link="${prefix}shoulder_roll" />
            <origin xyz="0 0 0.05315" rpy="1.5708 0 0" />
            <limit lower="-2.618" upper="2.618" effort="100.0" velocity="1.0" />
            <axis xyz="0 0 1" />
        </joint>

        <link name="${prefix}shoulder_roll">
            <visual>
                <origin xyz="0 0 0" rpy="0 0 0"/>
                <geometry>
                    <mesh filename="package://cyton_gamma_300_description/meshes/Shoulder_Roll.dae"/>
                </geometry>
            </visual>
            <collision>
                <origin xyz="0.0 0.069 0.0587"/>
                <geometry>
                    <box size="0.09829 0.18143 0.08392"/>
                </geometry>
            </collision>
        </link>

        <!-- Second motor located here -->
        <joint name="${prefix}shoulder_pitch_joint" type="revolute">
            <parent link="${prefix}shoulder_roll" />
            <child link="${prefix}shoulder_pitch" />
            <origin xyz="0.028 0 0.063" rpy="0 0 0" />
            <limit lower="-1.8326" upper="1.8326" effort="100.0" velocity="1.0" />
            <axis xyz="1 0 0" />
        </joint>

        <link name="${prefix}shoulder_pitch">
            <visual>
                <origin xyz="0 0 0" rpy="0 1.5708 0" />
                <geometry>
                    <mesh filename="package://cyton_gamma_300_description/meshes/Shoulder_Pitch.dae"/>
                </geometry>
            </visual>
            <collision>
                <origin xyz="-0.001 0.064 0.1745"/>
                <geometry>
                    <box size="0.0709 0.19363 0.083"/>
                </geometry>
            </collision>
        </link>

        <!-- Third motor located here -->
        <joint name="${prefix}elbow_roll_joint" type="revolute">
            <parent link="${prefix}shoulder_pitch" />
            <child link="${prefix}elbow_roll" />
            <origin xyz="-0.028 0 0.089" rpy="0 0 0" />
            <limit lower="-1.8326" upper="1.8326" effort="100.0" velocity="1.0" />
            <axis xyz="0 -1 0" />
        </joint>

        <link name="${prefix}elbow_roll">
            <visual>
                <origin xyz="0 0 0.0" rpy="0 0 0" />
                <geometry>
                    <mesh filename="package://cyton_gamma_300_description/meshes/Elbow_Roll.dae"/>
                </geometry>
            </visual>
            <collision>
                <origin xyz="-0.0225 0.039 0.3068"/>
                <geometry>
                    <box size="0.0717 0.1846 0.0756"/>
                </geometry>
            </collision>
        </link>

        <!-- Third motor located here -->
        <joint name="${prefix}elbow_pitch_joint" type="revolute">
            <parent link="${prefix}elbow_roll" />
            <child link="${prefix}elbow_pitch" />
            <origin xyz="0.018 -0.018 0.052" rpy="0 0 0" />
            <limit lower="-1.8326" upper="1.8326" effort="100.0" velocity="1.0" />
            <axis xyz="1 0 0" />
        </joint>

        <link name="${prefix}elbow_pitch">
            <visual>
                <!-- Not sure if this is the correct orientation. -->
                <origin xyz="0 0 0" rpy="1.5708 0 0.7854" />
                <geometry>
                    <mesh filename="package://cyton_gamma_300_description/meshes/Elbow_Pitch.dae"/>
                </geometry>
            </visual>
            <collision>
                <origin xyz="0.0346 0.0461 0.4228"/>
                <geometry>
                    <box size="0.0549 0.1557 0.076"/>
                </geometry>
            </collision>
        </link>

        <!-- Fourth motor located here -->
        <joint name="${prefix}elbow_yaw_joint" type="revolute">
            <parent link="${prefix}elbow_pitch" />
            <child link="${prefix}elbow_yaw" />
            <origin xyz="-0.018 0.018 0.072" rpy="0 0 0" />
            <limit lower="-1.8326" upper="1.8326" effort="100.0" velocity="1.0" />
            <axis xyz="0 -1 0" />
        </joint>

        <link name="${prefix}elbow_yaw">
            <visual>
                <origin xyz="0 0 0" rpy="1.5708 0 2.3562" />
                <geometry>
                    <mesh filename="package://cyton_gamma_300_description/meshes/Elbow_Yaw.dae"/>
                </geometry>
            </visual>
            <collision>
                <origin xyz="0.0172 0.0209 0.516"/>
                <geometry>
                    <box size="0.0535 0.1160 0.0402"/>
                </geometry>
            </collision>
        </link>

        <!-- Fifth motor located here -->
        <joint name="${prefix}wrist_pitch_joint" type="revolute">
            <parent link="${prefix}elbow_yaw" />
            <child link="${prefix}wrist_pitch" />
            <origin xyz="0.018 -0.018 0.0718" rpy="0 0 0" />
            <limit lower="-1.8326" upper="1.8326" effort="100.0" velocity="1.0" />
            <axis xyz="1 0 0" />
        </joint>

        <link name="${prefix}wrist_pitch">
            <visual>
                <origin xyz="0 0 0" rpy="1.5708 0 0.7854" />
                <geometry>
                    <mesh filename="package://cyton_gamma_300_description/meshes/Wrist_Pitch.dae"/>
                </geometry>
            </visual>
            <collision>
                <origin xyz="0.0257 0.0118 0.5617"/>
                <geometry>
                    <box size="0.026 0.0435 0.05185"/>
                </geometry>
            </collision>
        </link>

        <!-- Sixth motor located here -->
        <joint name="${prefix}wrist_roll_joint" type="revolute">
            <parent link="${prefix}wrist_pitch" />
            <child link="${prefix}wrist_roll" />
            <origin xyz="-0.018 0.018 0.051425" rpy="0 0 0" />
            <limit lower="-2.61799" upper="2.61799" effort="100.0" velocity="1.0" />
            <axis xyz="0 0 1" />
        </joint>

        <link name="${prefix}wrist_roll">
            <visual>
                <origin xyz="0 0 0" rpy="3.1416 0 -2.3562" />
                <geometry>
                    <mesh filename="package://cyton_gamma_300_description/meshes/Wrist_Roll.dae"/>
                </geometry>
            </visual>
            <collision>
                <origin xyz="-0.0063 -0.0014 0.6102"/>
                <geometry>
                    <box size="0.0518 0.0723 0.1004"/>
                </geometry>
            </collision>
        </link>

        <!-- Seventh motor located here -->
        <joint name="${prefix}gripper_joint" type="prismatic">
            <parent link="${prefix}wrist_roll" />
            <child link="${prefix}gripper_finger1" />
            <origin xyz="-0.01331 0.00485 0.077225" rpy="0 0 0" />
            <limit lower="-0.008" upper="0.008" effort="100.0" velocity="1.0" />
            <axis xyz="1 0 0" />
        </joint>

        <link name="${prefix}gripper_finger1">
            <visual>
                <origin xyz="0 0 0" rpy="0 0 0" />
                <geometry>
                    <mesh filename="package://cyton_gamma_300_description/meshes/Gripper_Finger1.dae"/>
                </geometry>
            </visual>
            <collision>
                <origin xyz="-0.0167 0.0172 0.7254"/>
                <geometry>
                    <box size="0.015 0.0229 0.0475"/>
                </geometry>
            </collision>
        </link>

        <!-- Eighth motor located here -->
        <joint name="${prefix}gripper_joint2" type="prismatic">
            <parent link="${prefix}wrist_roll" />
            <child link="${prefix}gripper_finger2" />
            <origin xyz="0.0098 0.00485 0.077225" rpy="0 0 0" />
            <limit lower="-0.008" upper="0.008" effort="100.0" velocity="1.0" />
            <mimic joint="${prefix}gripper_joint" multiplier="-1"/>
            <axis xyz="1 0 0" />
        </joint>

        <link name="${prefix}gripper_finger2">
            <visual>
                <origin xyz="0 0 0" rpy="0 0 0" />
                <geometry>
                    <mesh filename="package://cyton_gamma_300_description/meshes/Gripper_Finger2.dae"/>
                </geometry>
            </visual>
            <collision>
                <origin xyz="0.0132 0.0172 0.7254"/>
                <geometry>
                    <box size="0.015 0.0229 0.0475"/>
                </geometry>
            </collision>
        </link>

        <xacro:if value="${virtual_ee}"> <!-- virtual end-effector -->
            <joint name="${prefix}virtual_endeffector_joint" type="fixed">
                <parent link="${prefix}wrist_roll" />
                <child link="${prefix}virtual_endeffector" />
                <origin xyz="-0.002316 0.0079 0.079425" rpy="0 0 0" />
            </joint>

            <link name="${prefix}virtual_endeffector">
                <visual>
                    <origin xyz="0 0 0" rpy="0 0 0" />
                    <geometry>
                        <sphere radius="0.002" />
                    </geometry>
                    <material name="grey">
                        <color rgba="0.7 0.7 0.7 0.8" />
                    </material>
                </visual>
            </link>
        </xacro:if>
    </xacro:macro>

</robot>
