<?xml version="1.0"?>
<robot name="cyton_gamma_300" xmlns:xacro="http://www.ros.org/wiki/xacro">

	<!-- Import all Gazebo-customization elements, including Gazebo colors -->
	<xacro:include filename="$(find cyton_gamma_300_description)/urdf/cyton_gamma_300.gazebo" />
	<!-- Import Rviz colors -->
	<xacro:include filename="$(find cyton_gamma_300_description)/urdf/materials.xacro" />


	<!-- ########################################### -->
	<!-- #######! PROPERTIES !###################### -->
	<!-- ########################################### -->
	<xacro:property name="transmission" value="$(arg transmission)" />

	<!-- Used for fixing robot to Gazebo 'base_link' -->
	<link name="world">
	</link>

	<joint name="base_joint" type="fixed">
	  <parent link="world"/>
	  <child link="base_link"/>
	</joint>

    <xacro:macro name="cyton_gamma_300" params="virtual_ee">
        <!-- Base of robot here -->
        <!-- ########################################### -->
        <!-- #######! Base Link !####################### -->
        <!-- ########################################### -->
        <link name="base_link">
            <visual>
                <origin xyz="0 0 0" rpy="0 0 0"/>
                <geometry>
                    <mesh filename="package://cyton_gamma_300_description/meshes/gamma_base.dae"/>
                </geometry>
            </visual>
            <collision>
                <origin xyz="0 0.0 0.0"/>
                <geometry>
                    <mesh filename="package://cyton_gamma_300_description/meshes/gamma_base.dae"/>
                </geometry>
            </collision>
			<!-- Added for Gazebo simulation -->
			<!-- The inertia values are 'guessed' -->
			<inertial>
			  <origin xyz="0 0 0" rpy="0 0 0"/>
			  <mass value="9"/>
			  <inertia
				ixx="1.0" ixy="0.0" ixz="0.0"
				iyy="1.0" iyz="0.0"
				izz="1.0"/>
			</inertial>
        </link>
        <!-- ########################################### -->
        <!-- #######! End of Base Link !################ -->
        <!-- ########################################### -->

        <!-- First motor located here -->
        <!-- ########################################### -->
        <!-- #######! Shoulder Roll: joint & link !##### -->
        <!-- ########################################### -->
        <joint name="shoulder_roll_joint" type="revolute">
            <parent link="base_link" />
            <child link="shoulder_roll" />
            <origin xyz="0 0 0.05315" rpy="0 0 1.2" />
            <limit lower="-2.618" upper="2.618" effort="100.0" velocity="1.0" />
            <axis xyz="0 0 1" />
        </joint>

        <link name="shoulder_roll">
            <visual>
                <origin xyz="0 0 0" rpy="1.5708 0 3.14159"/>
                <geometry>
                    <mesh filename="package://cyton_gamma_300_description/meshes/Shoulder_Roll.dae"/>
                </geometry>
            </visual>
            <collision>
				<origin xyz="0 0 0" rpy="1.5708 0 3.14159" />
                <geometry>
                    <mesh filename="package://cyton_gamma_300_description/meshes/Shoulder_Roll.dae"/>
                </geometry>
            </collision>
			<!-- Added for Gazebo simulation -->
			<!-- The inertia values are 'guessed' -->
			<inertial>
			  <origin xyz="0 0 0" rpy="0 0 0"/>
			  <mass value="1"/>
			  <inertia
				ixx="1.0" ixy="0.0" ixz="0.0"
				iyy="1.0" iyz="0.0"
				izz="1.0"/>
			</inertial>
        </link>
        <!-- ########################################### -->
        <!-- #######! End of Shoulder Roll !############ -->
        <!-- ########################################### -->

        <!-- Second motor located here -->
        <!-- ########################################### -->
        <!-- #######! Shoulder Pitch: joint & link !#### -->
        <!-- ########################################### -->
        <joint name="shoulder_pitch_joint" type="revolute">
            <parent link="shoulder_roll" />
            <child link="shoulder_pitch" />
            <origin xyz="0 0 0.063" rpy="0.0 0 0" />
            <limit lower="-1.8326" upper="1.8326" effort="100.0" velocity="1.0" />
            <axis xyz="1 0 0" />
        </joint>

        <link name="shoulder_pitch">
            <visual>
                <origin xyz="0.028 0 0" rpy="0 1.5708 0" />
                <geometry>
                    <mesh filename="package://cyton_gamma_300_description/meshes/Shoulder_Pitch.dae"/>
                </geometry>
            </visual>
            <collision>
				<!-- <origin xyz="-0.001 0.064 0.1745"/> -->
				<origin xyz="0.028 0 0" rpy="0 1.5708 0" />
                <geometry>
					<!-- <box size="0.0709 0.19363 0.083"/> -->
                    <mesh filename="package://cyton_gamma_300_description/meshes/Shoulder_Pitch.dae"/>
                </geometry>
            </collision>
			<!-- Added for Gazebo simulation -->
			<!-- The inertia values are 'guessed' -->
			<inertial>
			  <origin xyz="0 0 0" rpy="0 0 0"/>
			  <mass value="1"/>
			  <inertia
				ixx="1.0" ixy="0.0" ixz="0.0"
				iyy="1.0" iyz="0.0"
				izz="1.0"/>
			</inertial>
        </link>
        <!-- ########################################### -->
        <!-- #######! End of Shoulder Pitch !########### -->
        <!-- ########################################### -->


        <!-- Third motor located here -->
        <!-- ########################################### -->
        <!-- #######! Elbow Roll: joint & link !######## -->
        <!-- ########################################### -->
        <joint name="elbow_roll_joint" type="revolute">
            <parent link="shoulder_pitch" />
            <child link="elbow_roll" />
            <origin xyz="0 0 0.089" rpy="0 0 1.2" />
            <limit lower="-1.8326" upper="1.8326" effort="100.0" velocity="1.0" />
            <axis xyz="0 0 1" />
        </joint>

        <link name="elbow_roll">
            <visual>
                <origin xyz="0 0 0" rpy="0 0 3.92699" />
                <geometry>
                    <mesh filename="package://cyton_gamma_300_description/meshes/Elbow_Roll.dae"/>
                </geometry>
            </visual>
            <collision>
				<origin xyz="0 0 0" rpy="0 0 3.92699" />
				<!-- <origin xyz="-0.0225 0.039 0.3068"/> -->
                <geometry>
					<!-- <box size="0.0717 0.1846 0.0756"/> -->
                    <mesh filename="package://cyton_gamma_300_description/meshes/Elbow_Roll.dae"/>
                </geometry>
            </collision>
			<!-- Added for Gazebo simulation -->
			<!-- The inertia values are 'guessed' -->
			<inertial>
			  <origin xyz="0 0 0" rpy="0 0 0"/>
			  <mass value="1"/>
			  <inertia
				ixx="1.0" ixy="0.0" ixz="0.0"
				iyy="1.0" iyz="0.0"
				izz="1.0"/>
			</inertial>
        </link>
        <!-- ########################################### -->
        <!-- #######! End of Elbow Roll !############### -->
        <!-- ########################################### -->

        <!-- Fourth motor located here -->
        <!-- ########################################### -->
        <!-- #######! Elbow Pitch: joint & link !####### -->
        <!-- ########################################### -->
        <joint name="elbow_pitch_joint" type="revolute">
            <parent link="elbow_roll" />
            <child link="elbow_pitch" />
            <origin xyz="0 0 0.052" rpy="1.2 0 0" />
            <limit lower="-1.8326" upper="1.8326" effort="100.0" velocity="1.0" />
            <axis xyz="1 0 0" />
        </joint>

        <link name="elbow_pitch">
            <visual>
                <!-- Not sure if this is the correct orientation. -->
                <origin xyz="0.027 0 0" rpy="1.5708 0 1.5708" />
                <geometry>
                    <mesh filename="package://cyton_gamma_300_description/meshes/Elbow_Pitch.dae"/>
                </geometry>
            </visual>
            <collision>
				<!-- Not sure if this is the correct orientation. -->
				<origin xyz="0.027 0 0" rpy="1.5708 0 1.5708" />
				<!-- <origin xyz="0.0346 0.0461 0.4228"/> -->
                <geometry>
					<!-- <box size="0.0549 0.1557 0.076"/> -->
                    <mesh filename="package://cyton_gamma_300_description/meshes/Elbow_Pitch.dae"/>
                </geometry>
            </collision>
			<!-- Added for Gazebo simulation -->
			<!-- The inertia values are 'guessed' -->
			<inertial>
			  <origin xyz="0 0 0" rpy="0 0 0"/>
			  <mass value="1"/>
			  <inertia
				ixx="1.0" ixy="0.0" ixz="0.0"
				iyy="1.0" iyz="0.0"
				izz="1.0"/>
			</inertial>
        </link>
        <!-- ########################################### -->
        <!-- #######! End of Elbow Pitch !############## -->
        <!-- ########################################### -->

        <!-- Fifth motor located here -->
        <!-- ########################################### -->
        <!-- #######! Elbow Yaw: joint & link !######### -->
        <!-- ########################################### -->
        <joint name="elbow_yaw_joint" type="revolute">
            <parent link="elbow_pitch" />
            <child link="elbow_yaw" />
            <origin xyz="0 0 0.072" rpy="0 -1.2 0" />
            <limit lower="-1.8326" upper="1.8326" effort="100.0" velocity="1.0" />
            <axis xyz="0 -1 0" />
        </joint>

        <link name="elbow_yaw">
            <visual>
                <origin xyz="0 0 0" rpy="1.5708 0 0" />
                <geometry>
                    <mesh filename="package://cyton_gamma_300_description/meshes/Elbow_Yaw.dae"/>
                </geometry>
            </visual>
            <collision>
                <origin xyz="0 0 0" rpy="1.5708 0 0" />
				<!-- <origin xyz="0.0172 0.0209 0.516"/> -->
                <geometry>
					<!-- <box size="0.0535 0.1160 0.0402"/> -->
                    <mesh filename="package://cyton_gamma_300_description/meshes/Elbow_Yaw.dae"/>
                </geometry>
            </collision>
			<!-- Added for Gazebo simulation -->
			<!-- The inertia values are 'guessed' -->
			<inertial>
			  <origin xyz="0 0 0" rpy="0 0 0"/>
			  <mass value="1"/>
			  <inertia
				ixx="1.0" ixy="0.0" ixz="0.0"
				iyy="1.0" iyz="0.0"
				izz="1.0"/>
			</inertial>
        </link>
        <!-- ########################################### -->
        <!-- #######! End of Elbow Yaw !################ -->
        <!-- ########################################### -->

        <!-- Sixth motor located here -->
        <!-- ########################################### -->
        <!-- #######! Wrist Pitch: joint & link !####### -->
        <!-- ########################################### -->
        <joint name="wrist_pitch_joint" type="revolute">
            <parent link="elbow_yaw" />
            <child link="wrist_pitch" />
            <origin xyz="0 0 0.0718" rpy="1.2 0 0" />
            <limit lower="-1.8326" upper="1.8326" effort="100.0" velocity="1.0" />
            <axis xyz="1 0 0" />
        </joint>

        <link name="wrist_pitch">
            <visual>
                <origin xyz="0.027 0 0" rpy="1.5708 0 1.5708" />
                <geometry>
                    <mesh filename="package://cyton_gamma_300_description/meshes/Wrist_Pitch.dae"/>
                </geometry>
            </visual>
            <collision>
				<!-- <origin xyz="0.0257 0.0118 0.5617"/> -->
                <origin xyz="0.027 0 0" rpy="1.5708 0 1.5708" />
                <geometry>
                    <mesh filename="package://cyton_gamma_300_description/meshes/Wrist_Pitch.dae"/>
					<!-- <box size="0.026 0.0435 0.05185"/> -->
                </geometry>
            </collision>
			<!-- Added for Gazebo simulation -->
			<!-- The inertia values are 'guessed' -->
			<inertial>
			  <origin xyz="0 0 0" rpy="0 0 0"/>
			  <mass value="1"/>
			  <inertia
				ixx="1.0" ixy="0.0" ixz="0.0"
				iyy="1.0" iyz="0.0"
				izz="1.0"/>
			</inertial>
        </link>
        <!-- ########################################### -->
        <!-- #######! End of Wrist Pitch !############## -->
        <!-- ########################################### -->

        <!-- Seventh motor located here -->
        <!-- ########################################### -->
        <!-- #######! Wrist Roll: joint & link !######## -->
        <!-- ########################################### -->
        <joint name="wrist_roll_joint" type="revolute">
            <parent link="wrist_pitch" />
            <child link="wrist_roll" />
            <origin xyz="0 0 0.051425" rpy="0 0 1.2" />
            <limit lower="-2.61799" upper="2.61799" effort="100.0" velocity="1.0" />
            <axis xyz="0 0 1" />
        </joint>

        <link name="wrist_roll">
            <visual>
                <origin xyz="0 0 0" rpy="0 3.14159 1.5708" />
                <geometry>
                    <mesh filename="package://cyton_gamma_300_description/meshes/Wrist_Roll.dae"/>
                </geometry>
            </visual>
            <collision>
                <origin xyz="0 0 0" rpy="0 3.14159 1.5708" />
				<!-- <origin xyz="-0.0063 -0.0014 0.6102"/> -->
                <geometry>
					<!-- <box size="0.0518 0.0723 0.1004"/> -->
                    <mesh filename="package://cyton_gamma_300_description/meshes/Wrist_Roll.dae"/>
                </geometry>
            </collision>
			<!-- Added for Gazebo simulation -->
			<!-- The inertia values are 'guessed' -->
			<inertial>
			  <origin xyz="0 0 0" rpy="0 0 0"/>
			  <mass value="1"/>
			  <inertia
				ixx="1.0" ixy="0.0" ixz="0.0"
				iyy="1.0" iyz="0.0"
				izz="1.0"/>
			</inertial>
        </link>
        <!-- ########################################### -->
        <!-- #######! End of Wrist Roll !############### -->
        <!-- ########################################### -->

        <!-- Eigth motor located here -->
        <!-- ########################################### -->
        <!-- #######! Gripper Finger 1: joint & link !## -->
        <!-- ########################################### -->
        <joint name="gripper_finger1_joint" type="prismatic">
            <parent link="wrist_roll" />
            <child link="gripper_finger1" />
            <origin xyz="-0.01331 0.00485 0.077225" rpy="0 0 0" />
            <limit lower="-0.008" upper="0.008" effort="100.0" velocity="1.0" />
            <axis xyz="1 0 0" />
        </joint>
        <link name="gripper_finger1">
            <visual>
				<origin xyz="-0.0005 -0.0097 -0.031"/>
                <geometry>
                    <mesh filename="package://cyton_gamma_300_description/meshes/Gripper_Finger1.dae"/>
                </geometry>
            </visual>
            <collision>
				<!-- <origin xyz="-0.0167 0.0172 0.7254"/> -->
				<origin xyz="-0.0005 -0.0097 -0.031"/>
                <geometry>
					<!-- <box size="0.015 0.0229 0.0475"/> -->
                    <mesh filename="package://cyton_gamma_300_description/meshes/Gripper_Finger1.dae"/>
                </geometry>
            </collision>
			<!-- Added for Gazebo simulation -->
			<!-- The inertia values are 'guessed' -->
			<inertial>
			  <origin xyz="0 0 0" rpy="0 0 0"/>
			  <mass value="0.5"/>
			  <inertia
				ixx="1.0" ixy="0.0" ixz="0.0"
				iyy="1.0" iyz="0.0"
				izz="1.0"/>
			</inertial>
        </link>
        <!-- ########################################### -->
        <!-- #######! End of Gripper Finger 1 !######### -->
        <!-- ########################################### -->

        <!-- Eighth motor located here -->
        <!-- ########################################### -->
        <!-- #######! Gripper Finger 2: joint & link !## -->
        <!-- ########################################### -->
        <joint name="gripper_finger2_joint" type="prismatic">
            <parent link="wrist_roll" />
            <child link="gripper_finger2" />
            <origin xyz="0.0098 0.00485 0.077225" rpy="0 0 0" />
            <limit lower="-0.008" upper="0.008" effort="100.0" velocity="1.0" />
			<mimic joint="gripper_finger1_joint" multiplier="-1"/> 
            <axis xyz="1 0 0" />
        </joint>

        <link name="gripper_finger2">
            <visual>
				<origin xyz="0.0005 -0.0097 -0.031"/>
                <geometry>
                    <mesh filename="package://cyton_gamma_300_description/meshes/Gripper_Finger2.dae"/>
                </geometry>
            </visual>
            <collision>
				<origin xyz="0.0005 -0.0097 -0.031"/>
                <geometry>
                    <mesh filename="package://cyton_gamma_300_description/meshes/Gripper_Finger2.dae"/>
					<!-- <box size="0.015 0.0229 0.0475"/> -->
                </geometry>
            </collision>
			<!-- Added for Gazebo simulation -->
			<!-- The inertia values are 'guessed' -->
			<inertial>
			  <origin xyz="0 0 0" rpy="0 0 0"/>
			  <mass value="0.5"/>
			  <inertia
				ixx="1.0" ixy="0.0" ixz="0.0"
				iyy="1.0" iyz="0.0"
				izz="1.0"/>
			</inertial>
        </link>
        <!-- ########################################### -->
        <!-- #######! End of Gripper Finger 2 !######### -->
        <!-- ########################################### -->

        <xacro:if value="${virtual_ee}"> <!-- virtual end-effector -->
			<!-- ########################################### -->
			<!-- ####! Virtual Endeffector: joint & link !## -->
			<!-- ########################################### -->
            <joint name="virtual_endeffector_joint" type="fixed">
                <parent link="wrist_roll" />
                <child link="virtual_endeffector" />
                <origin xyz="-0.002316 0.0079 0.079425" rpy="0 0 0" />
            </joint>

            <link name="virtual_endeffector">
                <visual>
                    <origin xyz="0 0 0" rpy="0 0 0" />
                    <geometry>
                        <sphere radius="0.01" />
                    </geometry>
                    <material name="grey">
                        <color rgba="0.2 0.2 0.2 0.4" />
                    </material>
                </visual>
				<!-- Added for Gazebo simulation -->
				<!-- The inertia values are 'guessed' -->
				<inertial>
				  <origin xyz="0 0 0" rpy="0 0 0"/>
				  <mass value="0.03"/>
				  <inertia
					ixx="1.0" ixy="0.0" ixz="0.0"
					iyy="1.0" iyz="0.0"
					izz="1.0"/>
				</inertial>
            </link>
			<!-- ########################################### -->
			<!-- #####! End of Virtual Endeffector !######## -->
			<!-- ########################################### -->
        </xacro:if>
    </xacro:macro>

  <xacro:cyton_gamma_300 virtual_ee="true" />

  <xacro:macro name="include_transmission" >
	<xacro:if value="${transmission == 'position'}">
		<xacro:include filename="$(find cyton_gamma_300_description)/urdf/transmissions_positionjointinterface.xml" />  
	</xacro:if>
	<xacro:if value="${transmission == 'effort'}">
	   <xacro:include filename="$(find cyton_gamma_300_description)/urdf/transmissions_effortjointinterface.xml" />  
	</xacro:if>
  </xacro:macro>

  <xacro:include_transmission  /> 

</robot>
